Workbook

Sheet Instructions & Method
B1: Instructions, principles and formulas
B2: 1. What this workbook answers
B3: A borrower can fund itself with a bond or with an amortising loan of the same amount. Loans are routinely priced by reading the borrower's own bond curve at the loan's weighted average life (WAL) — the 'shortcut'. That shortcut is biased: on an upward-sloping curve it UNDER-charges, so the borrower saves. This workbook measures that saving precisely, for (a) a FLOATING loan priced off the bond Z-spread curve and (b) a FIXED loan priced off the bond YTM curve.
B4: The saving is NET: before the WAL date the loan's exposure is short-dated and genuinely cheaper than the WAL point, so the borrower OVERPAYS there (loss phase); after the WAL the exposure is long-dated and dearer, so the borrower UNDERPAYS (benefit phase). The workbook reports both phases and the net — exactly, not as an approximation (see §4.6).
B5: 2. How to use it (5 minutes)
B6: 1) Tab 'Inputs', rows 4–10: currency (USD/EUR), amount, drawdown years x, repayment years y, and the over/under adjustment X in bp for each loan type (0 = loan priced exactly at the curve point equal to the WAL).
B7: 2) Tab 'Inputs', rows 28–57: paste the bond Z-spread curve (bp), the bond YTM curve (%) and the swap par curve (%) at 1Y…30Y. Leave cells BLANK where you have no point — the model linearly interpolates between known points and holds flat beyond the ends (flagged). You need at least one point per curve; in practice give at least 1Y, 2Y, 3Y, 5Y, 7Y, 10Y and every bond point you have. Credit curve to 20Y is enough for loans up to 20Y; for longer loans see the warning on Results.
B8: 3) Tab 'Inputs', rows 13–19: additional market inputs — recovery rate (default 40%), EUR swap basis, optional 6M fixing. Defaults are correct for standard cases; overrides are optional. Rows 22–24: optional fees/new-issue premium (default 0).
B9: 4) Read tab 'Results'. Green = borrower saves, red = borrower overpays. Check the 'Integrity checks' block reads OK and read the 'Warnings' block.
B10: 5) Nothing else to run: there is NO Goal Seek, Solver or macro. The credit-curve bootstrap is solved in closed form (§4.3), so everything recalculates live.
B11: 3. Principles (why the WAL shortcut is wrong)
B12: P1 — Quoted curves are SPOT averages. A 10Y Z-spread already averages credit risk over years 0–10. Money outstanding in year 15 costs the FORWARD (marginal) credit cost of year 15, not the 15Y spot spread. The model therefore converts each curve into piecewise-constant forward hazard rates λ (one per year) before pricing. Exposure-weighting the spot curve instead double-counts the early years and typically gets even the SIGN wrong.
... B54: Differences from the reference spec, all deliberate for precision: annual (not 5/10/20/30Y) hazard buckets; simple forwards DF(t−1)/DF(t) − 1 instead of ln(DF ratio), so a riskless floater prices exactly at par; swap-curve bootstrap with the correct fixed-leg day count; drawdown period; shortcut read on the curve at the exact WAL (not rounded); exact (not indicative) decomposition.

Sheet Inputs
B1: Loan vs Bond: WAL-pricing wedge calculator — INPUTS
B2: Edit only the yellow cells (blue text). Everything else recalculates live. Example values are ILLUSTRATIVE (a EUR BBB-type issuer) — replace them with today's market data.
B3: 1. Transaction (required)
B4: Currency | C4: EUR | F4: USD or EUR. Drives the default swap/YTM conventions and the money labels.
B5: Loan amount = bond amount | C5: 5000000000 | F5: Same amount for the loan and the bond alternative.
B6: Disbursement (drawdown) period x (years) | C6: 1 | F6: Linear: equal drawdowns every 6 months starting at signing (t = 0). 0 = fully drawn at signing. Multiples of 0.5.
B7: Repayment period y (years) | C7: 23 | F7: Starts after the drawdown period. Equal semi-annual instalments, first one 6m after the last drawdown period ends. Multiples of 0.5, > 0.
B8: FLOATING loan: margin vs Z-spread at WAL (bps) | C8: 0 | F8: 0 = loan margin exactly equals the bond Z-spread read at the loan's WAL. +10 = 10bp above; −10 = 10bp below.
B9: FIXED loan: rate vs YTM at WAL (bps) | C9: 0 | F9: 0 = loan fixed rate exactly equals the bond YTM read at the loan's WAL. +/− as above.
B10: Valuation / pricing date | C10: 46321 | F10: Date the market data below was observed. Informational.
B12: 2. Additional market inputs (needed for the precise calculation — see tab 'Data Sourcing')
B13: Recovery rate on default (R) | C13: 0.4 | F13: Senior unsecured market standard 40%. Result is very insensitive to R (λ scales by 1/(1−R), cost by (1−R)).
B14: EUR swap curve basis (EUR only) | C14: EURIBOR6M | F14: EURIBOR6M = EUR swaps vs 6M Euribor (annual 30/360 fixed leg). ESTR = €STR OIS (annual ACT/360). Use the curve your Z-spreads are quoted against. Ignored for USD (SOFR OIS).
B15: Swap fixed-leg accrual factor — override (blank = default) | F15: Leave blank. Default: USD SOFR OIS ACT/360 = 365.25/360; EUR vs 6M Euribor 30/360 = 1; EUR €STR ACT/360 = 365.25/360.
B16: Swap fixed-leg accrual factor USED | C16: =IF(C15<>"",C15,IF(C4="USD",365.25/360,IF(C14="ESTR",365.25/360,1))) -> 1 | F16: Formula — do not edit.
B17: Bond YTM compounding frequency — override (blank = default) | F17: Leave blank. Default: EUR bonds annual coupons = 1; USD bonds semi-annual = 2.
B18: Bond YTM compounding frequency USED | C18: =IF(C17<>"",C17,IF(C4="USD",2,1)) -> 1 | F18: Formula — do not edit.
B19: 6M floating-rate fixing (optional, %) | C19: 0.03019 | F19: Optional. USD: 6M Term SOFR; EUR: 6M EURIBOR (or 6M €STR OIS if basis = ESTR). Pins the 6-month discount factor. Blank = log-linear from 1Y swap.
B21: 3. Optional all-in cost adjustments (default 0 — the headline hazard wedge ignores them)
B22: Loan upfront / arrangement fee (bps flat, paid at signing) | C22: 0 | F22: Cost to the borrower of the loan route.
B23: Bond issuance costs (bps flat: fees, legal, rating, listing) | C23: 0 | F23: Cost to the borrower of the bond route.
B24: Bond new-issue premium (bps running) | C24: 0 | F24: Concession over the secondary curve a new bond would pay.
B26: 4. Curves — one row per year. Leave a cell BLANK where no data: the model interpolates linearly (flat beyond the ends, flagged).
B27: Tenor | C27: Bond Z-spread (bp) [floating calc] | D27: Bond YTM (%) [fixed calc] | E27: Swap par rate (%) [risk-free curve] | F27: Notes
B28: 1Y | C28: -19 | D28: 0.03032 | E28: 0.0327 | F28: Z-spread: bp over the swap curve in column E. YTM: % in the bond's own compounding (row 18). Swap: par rates, %.
B29: 2Y | C29: -15 | D29: 0.03242 | E29: 0.0342 | F29: Swap curve should reach the loan's final maturity (tenors up to 30Y available).
B30: 3Y | C30: -14 | D30: 0.03349 | E30: 0.0345
B31: 4Y | C31: -2 | D31: 0.03431 | E31: 0.0344
B32: 5Y | C32: 6 | D32: 0.03522 | E32: 0.0344
B33: 6Y | C33: 13 | D33: 0.03597 | E33: 0.0344
B34: 7Y | C34: 24 | D34: 0.03726 | E34: 0.0344
B35: 8Y | C35: 30 | D35: 0.03804 | E35: 0.0345
B36: 9Y | C36: 37 | D36: 0.03888
B37: 10Y | C37: 42 | D37: 0.03942 | E37: 0.0347
B38: 11Y | C38: 46 | D38: 0.03995
B39: 12Y
B40: 13Y
B41: 14Y | C41: 61 | D41: 0.04198
B42: 15Y | C42: 65 | D42: 0.04256 | E42: 0.0351
B43: 16Y
...

Sheet Results
B1: RESULTS — what the borrower saves (or overpays) by taking the loan priced off the bond curve at the WAL
B2: ="Currency: "&Inputs!C4&" | Amount: "&TEXT(Inputs!C5,"#,##0")&" | Drawdown "&TEXT(Inputs!C6,"0.0")&"y + repayment "&TEXT(Inputs!C7,"0.0")&"y | Market data as of "&TEXT(Inputs!C10,"dd-mmm-yyyy") -> Currency: EUR | Amount: 5000000000,0 | Drawdown 01y + repayment 23y | Market data as of 26-Oct-2026
B3: Sign convention: POSITIVE = borrower SAVES vs. the bond-equivalent (fair) cost of the same profile; NEGATIVE = borrower pays in excess.
B5: Metric | C5: FLOATING loan vs Z-spread curve | D5: FIXED loan vs YTM curve | F5: How to read it
B6: Loan profile
B7: Final maturity (years) | C7: =Calc_Floating!$E$26 -> 24 | D7: =Calc_Fixed!$E$26 -> 24
B8: Weighted average life, WAL (years) | C8: =Calc_Floating!$E$4 -> 12.5 | D8: =Calc_Fixed!$E$4 -> 12.5 | F8: Σ outstanding × time / amount, measured from signing (includes drawdown period).
B9: Risky annuity (PV of 1bp p.a. on the profile, in years) | C9: =Calc_Floating!$E$5 -> 9.0024448 | D9: =Calc_Fixed!$E$5 -> 8.9433309 | F9: Converts bp running into PV: PV = bp/10,000 × amount × annuity.
B10: Pricing
B11: Bond curve read at the WAL (Z-spread bp | YTM quoted basis) | C11: =Calc_Floating!$E$6 -> 53.5 | D11: =Calc_Fixed!$E$6 -> 0.040965 | F11: The market shortcut: linear interpolation of your curve at the exact WAL.
B12: Loan spread / rate CHARGED (shortcut + X) [fixed: s.a. equiv.] | C12: =Calc_Floating!$E$9 -> 0.00535 | D12: =Calc_Fixed!$E$9 -> 0.040553846 | F12: Floating: margin over the reference rate. Fixed: all-in fixed coupon, semi-annual equivalent.
B13: FAIR spread / rate for this exact profile (bond-equivalent cost) | C13: =Calc_Floating!$E$10 -> 0.0062322004 | D13: =Calc_Fixed!$E$10 -> 0.04135539 | F13: What it would cost to fund this exact drawdown/amortisation profile on the issuer's own bond curve (forward hazard rates, survival, recovery on outstanding balance).
B14: Headline: net saving
B15: NET saving, bp p.a. (fair − charged) | C15: =Calc_Floating!$E$11*10000 -> 8.8220045 | D15: =Calc_Fixed!$E$11*10000 -> 8.0154395 | F15: Net of the loss before WAL and the benefit after WAL (split below).
B16: Net saving as % of the bond-equivalent spread / rate | C16: =IFERROR(Calc_Floating!$E$11/Calc_Floating!$E$10,0) -> 0.14155521 | D16: =IFERROR(Calc_Fixed!$E$11/Calc_Fixed!$E$10,0) -> 0.019381849 | F16: Floating: relative to the fair credit spread. Fixed: relative to the fair all-in fixed rate.
B17: Bond-equivalent ALL-IN rate (annualised, s.a.) | C17: =Calc_Floating!$E$12+Calc_Floating!$E$10 -> 0.040708471 | D17: =Calc_Fixed!$E$10 -> 0.04135539 | F17: Floating: exposure-weighted forward reference rate + fair spread. Fixed: fair fixed rate.
B18: Loan ALL-IN rate (annualised, s.a.) | C18: =Calc_Floating!$E$12+Calc_Floating!$E$9 -> 0.039826271 | D18: =Calc_Fixed!$E$9 -> 0.040553846
B19: Net saving as % of the bond all-in rate | C19: =IFERROR(Calc_Floating!$E$11/(Calc_Floating!$E$12+Calc_Floating!$E$10),0) -> 0.021671176 | D19: =IFERROR(Calc_Fixed!$E$11/Calc_Fixed!$E$10,0) -> 0.019381849
B20: Total saving over the life, nominal (undiscounted) | C20: =Calc_Floating!$E$11*Inputs!$C$5*Calc_Floating!$E$4 -> 55137528 | D20: =Calc_Fixed!$E$11*Inputs!$C$5*Calc_Fixed!$E$4 -> 50096497 | E20: =Inputs!$C$4 -> EUR | F20: bp × amount × WAL (= bp × principal-years).
B21: Total saving over the life, PRESENT VALUE | C21: =Calc_Floating!$E$13*Inputs!$C$5 -> 39709804 | D21: =Calc_Fixed!$E$13*Inputs!$C$5 -> 35842364 | E21: =Inputs!$C$4 -> EUR | F21: Exact: survival-weighted and discounted. This is the economic value transferred to the borrower today.
B22: Average saving per year of loan life (nominal) | C22: =IFERROR(Calc_Floating!$E$11*Inputs!$C$5*Calc_Floating!$E$4/Calc_Floating!$E$26,0) -> 2297397 | D22: =IFERROR(Calc_Fixed!$E$11*Inputs!$C$5*Calc_Fixed!$E$4/Calc_Fixed!$E$26,0) -> 2087354 | E22: =Inputs!$C$4 -> EUR
B23: Decomposition: loss before WAL vs benefit after WAL (EXACT — sums to the net)
B24: LOSS phase (start → WAL): PV, money | C24: =Calc_Floating!$E$15*Inputs!$C$5 -> -26278306 | D24: =Calc_Fixed!$E$15*Inputs!$C$5 -> -27401522 | E24: =Inputs!$C$4 -> EUR | F24: Usually negative: early exposure is cheaper than the WAL point, so the borrower overpays here.
B25: BENEFIT phase (WAL → maturity): PV, money | C25: =Calc_Floating!$E$14*Inputs!$C$5 -> 65988110 | D25: =Calc_Fixed!$E$14*Inputs!$C$5 -> 63243886 | E25: =Inputs!$C$4 -> EUR | F25: Usually positive: late exposure is dearer than the WAL point, so the borrower underpays here.
B26: NET (= loss + benefit) | C26: =C24+C25 -> 39709804 | D26: =D24+D25 -> 35842364 | E26: =Inputs!$C$4 -> EUR | F26: Equals the PV total above.
B27: LOSS phase, contribution to net (bp p.a.) | C27: =Calc_Floating!$E$15/Calc_Floating!$E$5*10000 -> -5.8380377 | D27: =Calc_Fixed!$E$15/Calc_Fixed!$E$5*10000 -> -6.1278112
B28: BENEFIT phase, contribution to net (bp p.a.) | C28: =Calc_Floating!$E$14/Calc_Floating!$E$5*10000 -> 14.660042 | D28: =Calc_Fixed!$E$14/Calc_Fixed!$E$5*10000 -> 14.143251
B29: Principal-years before WAL | C29: =Calc_Floating!$E$17 -> 9.5 | D29: =Calc_Fixed!$E$17 -> 9.5
B30: Principal-years after WAL | C30: =Calc_Floating!$E$16 -> 3 | D30: =Calc_Fixed!$E$16 -> 3 | F30: WAL equalises the QUANTITY of principal-years; it does not put them at the same point in time as a bullet.
B31: Avg fair spread / rate on exposure BEFORE WAL | C31: =Calc_Floating!$E$20 -> 0.0046612849 | D31: =Calc_Fixed!$E$20 -> 0.039833198
B32: Avg fair spread / rate on exposure AFTER WAL | C32: =Calc_Floating!$E$19 -> 0.01497393 | D32: =Calc_Fixed!$E$19 -> 0.050002788
B33: Fixed loan only: where the fixed-rate saving comes from
B34: Risk-free curve effect (bp): profile-weighted fwd − rf par yield at WAL | C34: ="n/a" -> n/a | D34: =(Calc_Fixed!$E$12-Calc_Fixed!$E$25)*10000 -> -1.2327166 | F34: Reading a fixed rate at the WAL also misprices the risk-free term structure. This part is not credit.
B35: Credit / hazard effect (bp) = net − risk-free effect | C35: ="n/a" -> n/a | D35: =Calc_Fixed!$E$11*10000-D34 -> 9.2481561 | F35: The pure net hazard-cost saving inside the fixed-rate wedge.
B36: Optional: all-in incl. fees / new-issue premium (Inputs rows 22–24)
B37: Loan upfront fee, running equivalent (bp p.a.) | C37: =Inputs!$C$22/Calc_Floating!$E$5 -> 0 | D37: =Inputs!$C$22/Calc_Fixed!$E$5 -> 0
B38: Bond issuance costs, running equivalent (bp p.a.) | C38: =Inputs!$C$23/Calc_Floating!$E$5 -> 0 | D38: =Inputs!$C$23/Calc_Fixed!$E$5 -> 0
B39: Bond new-issue premium (bp p.a.) | C39: =Inputs!$C$24 -> 0 | D39: =Inputs!$C$24 -> 0
B40: NET saving incl. costs (bp p.a.) | C40: =Calc_Floating!$E$11*10000-C37+C38+C39 -> 8.8220045 | D40: =Calc_Fixed!$E$11*10000-D37+D38+D39 -> 8.0154395
B41: NET saving incl. costs, PV money | C41: =C40/10000*Inputs!$C$5*Calc_Floating!$E$5 -> 39709804 | D41: =D40/10000*Inputs!$C$5*Calc_Fixed!$E$5 -> 35842364 | E41: =Inputs!$C$4 -> EUR
...

Sheet Data Sourcing
B1: Data Sourcing — how to obtain the inputs (by currency)
B2: Bottom line: the swap curve can be obtained free and reliably from the open internet. The BOND curves (Z-spread and YTM by tenor for a specific issuer) are NOT reliably available free — use Bloomberg (or your bank's pricing). Recovery rate: use 40% unless you have a reason not to.
B3: A. Inputs you must supply and why
B4: 1 Bond Z-spread curve 1Y–20Y (bp) → floating calculation. The issuer's own senior unsecured curve, same currency as the loan. 2 Bond YTM curve 1Y–20Y (%) → fixed calculation. Same issuer/seniority/currency. 3 Swap par curve 1Y–30Y (%) → ADDITIONAL INPUT: risk-free discount factors and forward reference rates. 4 Recovery rate → ADDITIONAL INPUT: default 40% senior unsecured. 5 6M fixing (optional) → ADDITIONAL INPUT: pins the first 6 months of the curve. Forward rates are NOT an input: the workbook derives them from the swap curve.
B5: B. Swap curve — USD (SOFR OIS, annual/annual, ACT/360)
B6: Free / open internet: • Chatham Financial — US market rates page, 'SOFR swap rate (annual/annual)' table, 1Y–30Y, mid-market, end of day: https://www.chathamfinancial.com/technology/us-market-rates (a free login gives hourly-refreshed rates and history). • ICE Benchmark Administration — USD SOFR ICE Swap Rate, published daily around 11:15 New York time, tenors 1Y–30Y: https://www.ice.com/iba/ice-swap-rate (access terms apply; widely redistributed by data vendors). • 6M fixing: CME Term SOFR 6M (cmegroup.com, Term SOFR page; free with registration).
B7: Bloomberg: • Tickers USOSFR1 Curncy … USOSFR10, USOSFR12, USOSFR15, USOSFR20, USOSFR25, USOSFR30 Curncy (USD SOFR OIS par swaps). Quickest: type USOSFR10 Curncy <GO>, or open curve S490 in ICVS <GO> / SWDF <GO> and export the par rates. • 6M fixing: TSFR6M Index. • IMPORTANT: in YAS on your bonds, check which curve the Z-spread is computed against (the curve shown next to Z-spread) — use that same curve here.
B8: Settings for USD: Currency = USD (row 4) sets accrual 365.25/360 and YTM compounding 2 automatically.
B9: C. Swap curve — EUR
B10: Which EUR curve? Use the curve your Z-spreads are measured against. Bloomberg's default for EUR corporate bonds is typically the EUR swap curve vs 6M EURIBOR; if your Z-spreads are vs €STR, set row 14 to ESTR.
B11: Free / open internet: • Chatham Financial — European market rates (EURIBOR swap rates): https://www.chathamfinancial.com/technology/european-market-rates • ICE Benchmark Administration — EUR EURIBOR ICE Swap Rate (published ~11:15 CET) and EUR €STR ICE Swap Rate, 1Y–30Y: https://www.ice.com/iba/ice-swap-rate • 6M EURIBOR fixing: EMMI (euribor-rates.eu / emmi-benchmarks.eu; free with a 24h delay). €STR daily rate: ECB website (ecb.europa.eu) — note this is overnight, not a swap curve.
B12: Bloomberg: • vs 6M EURIBOR (annual 30/360 fixed): EUSA1 Curncy … EUSA10, EUSA12, EUSA15, EUSA20, EUSA25, EUSA30 Curncy; 6M fixing EUR006M Index. Curve in ICVS: S45. • vs €STR (annual ACT/360): EESWE1 Curncy … EESWE30 Curncy; curve in ICVS: S514. Set row 14 = ESTR. Settings for EUR: Currency = EUR sets YTM compounding 1 (annual coupons) and accrual 1 (vs Euribor) or 365.25/360 (€STR).
... B19: ☐ Same date for swap and bond data ☐ Z-spreads measured against the swap curve you entered ☐ Bonds: same issuer, seniority, currency as the loan ☐ Mid quotes throughout ☐ Results → Integrity checks = OK ☐ Results → Warnings reviewed (maturity beyond last bond point?)

Sheet Curves
A1: Curve preparation: gap-filling, YTM conversion, swap bootstrap, semi-annual risk-free grid
A2: Calculation sheet — no inputs here.
A4: Year k | B4: Z raw (bp) | C4: prev idx | D4: next idx | E4: Z filled (bp) | F4: Z status | G4: YTM raw | H4: prev idx | I4: next idx | J4: YTM filled (quoted basis) | K4: YTM s.a.-equivalent | L4: YTM status | M4: Swap raw | N4: prev idx | O4: next idx | P4: Swap filled | Q4: Annual DF | R4: Σ DF (annuity) | S4: Swap status | U4: i | V4: t (y) | W4: DF(t) | X4: f·a = DF(i−1)/DF(i) − 1 | Y4: Σ DF (s.a.) | Z4: Risk-free par yield s.a. (bullet to t)
A5: 1 | B5: =IF(Inputs!C28="","",Inputs!C28) -> -19 | C5: =IF(B5<>"",A5,0) -> 1 | D5: =IF(B5<>"",A5,D6) -> 1 | E5: =IF(B5<>"",B5,IF(AND(C5>0,D5>0),INDEX($B$5:$B$34,C5)+(INDEX($B$5:$B$34,D5)-INDEX($B$5:$B$34,C5))*(A5-C5)/(D5-C5),IF(C5>0,INDEX($B$5:$B$34,C5),IF(D5>0,INDEX($B$5:$B$34,D5),NA())))) -> -19 | F5: =IF(B5<>"","quoted",IF(AND(C5>0,D5>0),"interpolated","flat extrapolation")) -> quoted | G5: =IF(Inputs!D28="","",Inputs!D28) -> 0.03032 | H5: =IF(G5<>"",A5,0) -> 1 | I5: =IF(G5<>"",A5,I6) -> 1 | J5: =IF(G5<>"",G5,IF(AND(H5>0,I5>0),INDEX($G$5:$G$34,H5)+(INDEX($G$5:$G$34,I5)-INDEX($G$5:$G$34,H5))*(A5-H5)/(I5-H5),IF(H5>0,INDEX($G$5:$G$34,H5),IF(I5>0,INDEX($G$5:$G$34,I5),NA())))) -> 0.03032 | K5: =2*((1+J5/Inputs!$C$18)^(Inputs!$C$18/2)-1) -> 0.030093594 | L5: =IF(G5<>"","quoted",IF(AND(H5>0,I5>0),"interpolated","flat extrapolation")) -> quoted | M5: =IF(Inputs!E28="","",Inputs!E28) -> 0.0327 | N5: =IF(M5<>"",A5,0) -> 1 | O5: =IF(M5<>"",A5,O6) -> 1 | P5: =IF(M5<>"",M5,IF(AND(N5>0,O5>0),INDEX($M$5:$M$34,N5)+(INDEX($M$5:$M$34,O5)-INDEX($M$5:$M$34,N5))*(A5-N5)/(O5-N5),IF(N5>0,INDEX($M$5:$M$34,N5),IF(O5>0,INDEX($M$5:$M$34,O5),NA())))) -> 0.0327 | Q5: =1/(1+P5*Inputs!$C$16) -> 0.96833543 | R5: =Q5 -> 0.96833543 | S5: =IF(M5<>"","quoted",IF(AND(N5>0,O5>0),"interpolated","flat extrapolation")) -> quoted | U5: 0 | V5: =U5/2 -> 0 | W5: 1 | Y5: 0
A6: 2 | B6: =IF(Inputs!C29="","",Inputs!C29) -> -15 | C6: =IF(B6<>"",A6,C5) -> 2 | D6: =IF(B6<>"",A6,D7) -> 2 | E6: =IF(B6<>"",B6,IF(AND(C6>0,D6>0),INDEX($B$5:$B$34,C6)+(INDEX($B$5:$B$34,D6)-INDEX($B$5:$B$34,C6))*(A6-C6)/(D6-C6),IF(C6>0,INDEX($B$5:$B$34,C6),IF(D6>0,INDEX($B$5:$B$34,D6),NA())))) -> -15 | F6: =IF(B6<>"","quoted",IF(AND(C6>0,D6>0),"interpolated","flat extrapolation")) -> quoted | G6: =IF(Inputs!D29="","",Inputs!D29) -> 0.03242 | H6: =IF(G6<>"",A6,H5) -> 2 | I6: =IF(G6<>"",A6,I7) -> 2 | J6: =IF(G6<>"",G6,IF(AND(H6>0,I6>0),INDEX($G$5:$G$34,H6)+(INDEX($G$5:$G$34,I6)-INDEX($G$5:$G$34,H6))*(A6-H6)/(I6-H6),IF(H6>0,INDEX($G$5:$G$34,H6),IF(I6>0,INDEX($G$5:$G$34,I6),NA())))) -> 0.03242 | K6: =2*((1+J6/Inputs!$C$18)^(Inputs!$C$18/2)-1) -> 0.032161411 | L6: =IF(G6<>"","quoted",IF(AND(H6>0,I6>0),"interpolated","flat extrapolation")) -> quoted | M6: =IF(Inputs!E29="","",Inputs!E29) -> 0.0342 | N6: =IF(M6<>"",A6,N5) -> 2 | O6: =IF(M6<>"",A6,O7) -> 2 | P6: =IF(M6<>"",M6,IF(AND(N6>0,O6>0),INDEX($M$5:$M$34,N6)+(INDEX($M$5:$M$34,O6)-INDEX($M$5:$M$34,N6))*(A6-N6)/(O6-N6),IF(N6>0,INDEX($M$5:$M$34,N6),IF(O6>0,INDEX($M$5:$M$34,O6),NA())))) -> 0.0342 | Q6: =(1-P6*Inputs!$C$16*R5)/(1+P6*Inputs!$C$16) -> 0.93490904 | R6: =R5+Q6 -> 1.9032445 | S6: =IF(M6<>"","quoted",IF(AND(N6>0,O6>0),"interpolated","flat extrapolation")) -> quoted | U6: 1 | V6: =U6/2 -> 0.5 | W6: =IF(Inputs!$C$19<>"",1/(1+Inputs!$C$19*182.5/360),SQRT(1*INDEX($Q$5:$Q$34,1))) -> 0.98492605 | X6: =W5/W6-1 -> 0.015304653 | Y6: =Y5+W6 -> 0.98492605 | Z6: =(1-W6)/(0.5*Y6) -> 0.030609306
A7: 3 | B7: =IF(Inputs!C30="","",Inputs!C30) -> -14 | C7: =IF(B7<>"",A7,C6) -> 3 | D7: =IF(B7<>"",A7,D8) -> 3 | E7: =IF(B7<>"",B7,IF(AND(C7>0,D7>0),INDEX($B$5:$B$34,C7)+(INDEX($B$5:$B$34,D7)-INDEX($B$5:$B$34,C7))*(A7-C7)/(D7-C7),IF(C7>0,INDEX($B$5:$B$34,C7),IF(D7>0,INDEX($B$5:$B$34,D7),NA())))) -> -14 | F7: =IF(B7<>"","quoted",IF(AND(C7>0,D7>0),"interpolated","flat extrapolation")) -> quoted | G7: =IF(Inputs!D30="","",Inputs!D30) -> 0.03349 | H7: =IF(G7<>"",A7,H6) -> 3 | I7: =IF(G7<>"",A7,I8) -> 3 | J7: =IF(G7<>"",G7,IF(AND(H7>0,I7>0),INDEX($G$5:$G$34,H7)+(INDEX($G$5:$G$34,I7)-INDEX($G$5:$G$34,H7))*(A7-H7)/(I7-H7),IF(H7>0,INDEX($G$5:$G$34,H7),IF(I7>0,INDEX($G$5:$G$34,I7),NA())))) -> 0.03349 | K7: =2*((1+J7/Inputs!$C$18)^(Inputs!$C$18/2)-1) -> 0.033214204 | L7: =IF(G7<>"","quoted",IF(AND(H7>0,I7>0),"interpolated","flat extrapolation")) -> quoted | M7: =IF(Inputs!E30="","",Inputs!E30) -> 0.0345 | N7: =IF(M7<>"",A7,N6) -> 3 | O7: =IF(M7<>"",A7,O8) -> 3 | P7: =IF(M7<>"",M7,IF(AND(N7>0,O7>0),INDEX($M$5:$M$34,N7)+(INDEX($M$5:$M$34,O7)-INDEX($M$5:$M$34,N7))*(A7-N7)/(O7-N7),IF(N7>0,INDEX($M$5:$M$34,N7),IF(O7>0,INDEX($M$5:$M$34,O7),NA())))) -> 0.0345 | Q7: =(1-P7*Inputs!$C$16*R6)/(1+P7*Inputs!$C$16) -> 0.90317841 | R7: =R6+Q7 -> 2.8064229 | S7: =IF(M7<>"","quoted",IF(AND(N7>0,O7>0),"interpolated","flat extrapolation")) -> quoted | U7: 2 | V7: =U7/2 -> 1 | W7: =INDEX($Q$5:$Q$34,1) -> 0.96833543 | X7: =W6/W7-1 -> 0.017133131 | Y7: =Y6+W7 -> 1.9532615 | Z7: =(1-W7)/(0.5*Y7) -> 0.032422253
A8: 4 | B8: =IF(Inputs!C31="","",Inputs!C31) -> -2 | C8: =IF(B8<>"",A8,C7) -> 4 | D8: =IF(B8<>"",A8,D9) -> 4 | E8: =IF(B8<>"",B8,IF(AND(C8>0,D8>0),INDEX($B$5:$B$34,C8)+(INDEX($B$5:$B$34,D8)-INDEX($B$5:$B$34,C8))*(A8-C8)/(D8-C8),IF(C8>0,INDEX($B$5:$B$34,C8),IF(D8>0,INDEX($B$5:$B$34,D8),NA())))) -> -2 | F8: =IF(B8<>"","quoted",IF(AND(C8>0,D8>0),"interpolated","flat extrapolation")) -> quoted | G8: =IF(Inputs!D31="","",Inputs!D31) -> 0.03431 | H8: =IF(G8<>"",A8,H7) -> 4 | I8: =IF(G8<>"",A8,I9) -> 4 | J8: =IF(G8<>"",G8,IF(AND(H8>0,I8>0),INDEX($G$5:$G$34,H8)+(INDEX($G$5:$G$34,I8)-INDEX($G$5:$G$34,H8))*(A8-H8)/(I8-H8),IF(H8>0,INDEX($G$5:$G$34,H8),IF(I8>0,INDEX($G$5:$G$34,I8),NA())))) -> 0.03431 | K8: =2*((1+J8/Inputs!$C$18)^(Inputs!$C$18/2)-1) -> 0.034020649 | L8: =IF(G8<>"","quoted",IF(AND(H8>0,I8>0),"interpolated","flat extrapolation")) -> quoted | M8: =IF(Inputs!E31="","",Inputs!E31) -> 0.0344 | N8: =IF(M8<>"",A8,N7) -> 4 | O8: =IF(M8<>"",A8,O9) -> 4 | P8: =IF(M8<>"",M8,IF(AND(N8>0,O8>0),INDEX($M$5:$M$34,N8)+(INDEX($M$5:$M$34,O8)-INDEX($M$5:$M$34,N8))*(A8-N8)/(O8-N8),IF(N8>0,INDEX($M$5:$M$34,N8),IF(O8>0,INDEX($M$5:$M$34,O8),NA())))) -> 0.0344 | Q8: =(1-P8*Inputs!$C$16*R7)/(1+P8*Inputs!$C$16) -> 0.87341362 | R8: =R7+Q8 -> 3.6798365 | S8: =IF(M8<>"","quoted",IF(AND(N8>0,O8>0),"interpolated","flat extrapolation")) -> quoted | U8: 3 | V8: =U8/2 -> 1.5 | W8: =SQRT(INDEX($Q$5:$Q$34,1)*INDEX($Q$5:$Q$34,2)) -> 0.95147546 | X8: =W7/W8-1 -> 0.017719819 | Y8: =Y7+W8 -> 2.9047369 | Z8: =(1-W8)/(0.5*Y8) -> 0.033410627
A9: 5 | B9: =IF(Inputs!C32="","",Inputs!C32) -> 6 | C9: =IF(B9<>"",A9,C8) -> 5 | D9: =IF(B9<>"",A9,D10) -> 5 | E9: =IF(B9<>"",B9,IF(AND(C9>0,D9>0),INDEX($B$5:$B$34,C9)+(INDEX($B$5:$B$34,D9)-INDEX($B$5:$B$34,C9))*(A9-C9)/(D9-C9),IF(C9>0,INDEX($B$5:$B$34,C9),IF(D9>0,INDEX($B$5:$B$34,D9),NA())))) -> 6 | F9: =IF(B9<>"","quoted",IF(AND(C9>0,D9>0),"interpolated","flat extrapolation")) -> quoted | G9: =IF(Inputs!D32="","",Inputs!D32) -> 0.03522 | H9: =IF(G9<>"",A9,H8) -> 5 | I9: =IF(G9<>"",A9,I10) -> 5 | J9: =IF(G9<>"",G9,IF(AND(H9>0,I9>0),INDEX($G$5:$G$34,H9)+(INDEX($G$5:$G$34,I9)-INDEX($G$5:$G$34,H9))*(A9-H9)/(I9-H9),IF(H9>0,INDEX($G$5:$G$34,H9),IF(I9>0,INDEX($G$5:$G$34,I9),NA())))) -> 0.03522 | K9: =2*((1+J9/Inputs!$C$18)^(Inputs!$C$18/2)-1) -> 0.034915232 | L9: =IF(G9<>"","quoted",IF(AND(H9>0,I9>0),"interpolated","flat extrapolation")) -> quoted | M9: =IF(Inputs!E32="","",Inputs!E32) -> 0.0344 | N9: =IF(M9<>"",A9,N8) -> 5 | O9: =IF(M9<>"",A9,O10) -> 5 | P9: =IF(M9<>"",M9,IF(AND(N9>0,O9>0),INDEX($M$5:$M$34,N9)+(INDEX($M$5:$M$34,O9)-INDEX($M$5:$M$34,N9))*(A9-N9)/(O9-N9),IF(N9>0,INDEX($M$5:$M$34,N9),IF(O9>0,INDEX($M$5:$M$34,O9),NA())))) -> 0.0344 | Q9: =(1-P9*Inputs!$C$16*R8)/(1+P9*Inputs!$C$16) -> 0.84436739 | R9: =R8+Q9 -> 4.5242039 | S9: =IF(M9<>"","quoted",IF(AND(N9>0,O9>0),"interpolated","flat extrapolation")) -> quoted | U9: 4 | V9: =U9/2 -> 2 | W9: =INDEX($Q$5:$Q$34,2) -> 0.93490904 | X9: =W8/W9-1 -> 0.017719819 | Y9: =Y8+W9 -> 3.839646 | Z9: =(1-W9)/(0.5*Y9) -> 0.033904668
A10: 6 | B10: =IF(Inputs!C33="","",Inputs!C33) -> 13 | C10: =IF(B10<>"",A10,C9) -> 6 | D10: =IF(B10<>"",A10,D11) -> 6 | E10: =IF(B10<>"",B10,IF(AND(C10>0,D10>0),INDEX($B$5:$B$34,C10)+(INDEX($B$5:$B$34,D10)-INDEX($B$5:$B$34,C10))*(A10-C10)/(D10-C10),IF(C10>0,INDEX($B$5:$B$34,C10),IF(D10>0,INDEX($B$5:$B$34,D10),NA())))) -> 13 | F10: =IF(B10<>"","quoted",IF(AND(C10>0,D10>0),"interpolated","flat extrapolation")) -> quoted | G10: =IF(Inputs!D33="","",Inputs!D33) -> 0.03597 | H10: =IF(G10<>"",A10,H9) -> 6 | I10: =IF(G10<>"",A10,I11) -> 6 | J10: =IF(G10<>"",G10,IF(AND(H10>0,I10>0),INDEX($G$5:$G$34,H10)+(INDEX($G$5:$G$34,I10)-INDEX($G$5:$G$34,H10))*(A10-H10)/(I10-H10),IF(H10>0,INDEX($G$5:$G$34,H10),IF(I10>0,INDEX($G$5:$G$34,I10),NA())))) -> 0.03597 | K10: =2*((1+J10/Inputs!$C$18)^(Inputs!$C$18/2)-1) -> 0.03565223 | L10: =IF(G10<>"","quoted",IF(AND(H10>0,I10>0),"interpolated","flat extrapolation")) -> quoted | M10: =IF(Inputs!E33="","",Inputs!E33) -> 0.0344 | N10: =IF(M10<>"",A10,N9) -> 6 | O10: =IF(M10<>"",A10,O11) -> 6 | P10: =IF(M10<>"",M10,IF(AND(N10>0,O10>0),INDEX($M$5:$M$34,N10)+(INDEX($M$5:$M$34,O10)-INDEX($M$5:$M$34,N10))*(A10-N10)/(O10-N10),IF(N10>0,INDEX($M$5:$M$34,N10),IF(O10>0,INDEX($M$5:$M$34,O10),NA())))) -> 0.0344 | Q10: =(1-P10*Inputs!$C$16*R9)/(1+P10*Inputs!$C$16) -> 0.81628711 | R10: =R9+Q10 -> 5.340491 | S10: =IF(M10<>"","quoted",IF(AND(N10>0,O10>0),"interpolated","flat extrapolation")) -> quoted | U10: 5 | V10: =U10/2 -> 2.5 | W10: =SQRT(INDEX($Q$5:$Q$34,2)*INDEX($Q$5:$Q$34,3)) -> 0.91890677 | X10: =W9/W10-1 -> 0.017414459 | Y10: =Y9+W10 -> 4.7585528 | Z10: =(1-W10)/(0.5*Y10) -> 0.034083147
A11: 7 | B11: =IF(Inputs!C34="","",Inputs!C34) -> 24 | C11: =IF(B11<>"",A11,C10) -> 7 | D11: =IF(B11<>"",A11,D12) -> 7 | E11: =IF(B11<>"",B11,IF(AND(C11>0,D11>0),INDEX($B$5:$B$34,C11)+(INDEX($B$5:$B$34,D11)-INDEX($B$5:$B$34,C11))*(A11-C11)/(D11-C11),IF(C11>0,INDEX($B$5:$B$34,C11),IF(D11>0,INDEX($B$5:$B$34,D11),NA())))) -> 24 | F11: =IF(B11<>"","quoted",IF(AND(C11>0,D11>0),"interpolated","flat extrapolation")) -> quoted | G11: =IF(Inputs!D34="","",Inputs!D34) -> 0.03726 | H11: =IF(G11<>"",A11,H10) -> 7 | I11: =IF(G11<>"",A11,I12) -> 7 | J11: =IF(G11<>"",G11,IF(AND(H11>0,I11>0),INDEX($G$5:$G$34,H11)+(INDEX($G$5:$G$34,I11)-INDEX($G$5:$G$34,H11))*(A11-H11)/(I11-H11),IF(H11>0,INDEX($G$5:$G$34,H11),IF(I11>0,INDEX($G$5:$G$34,I11),NA())))) -> 0.03726 | K11: =2*((1+J11/Inputs!$C$18)^(Inputs!$C$18/2)-1) -> 0.036919242 | L11: =IF(G11<>"","quoted",IF(AND(H11>0,I11>0),"interpolated","flat extrapolation")) -> quoted | M11: =IF(Inputs!E34="","",Inputs!E34) -> 0.0344 | N11: =IF(M11<>"",A11,N10) -> 7 | O11: =IF(M11<>"",A11,O12) -> 7 | P11: =IF(M11<>"",M11,IF(AND(N11>0,O11>0),INDEX($M$5:$M$34,N11)+(INDEX($M$5:$M$34,O11)-INDEX($M$5:$M$34,N11))*(A11-N11)/(O11-N11),IF(N11>0,INDEX($M$5:$M$34,N11),IF(O11>0,INDEX($M$5:$M$34,O11),NA())))) -> 0.0344 | Q11: =(1-P11*Inputs!$C$16*R10)/(1+P11*Inputs!$C$16) -> 0.78914067 | R11: =R10+Q11 -> 6.1296317 | S11: =IF(M11<>"","quoted",IF(AND(N11>0,O11>0),"interpolated","flat extrapolation")) -> quoted | U11: 6 | V11: =U11/2 -> 3 | W11: =INDEX($Q$5:$Q$34,3) -> 0.90317841 | X11: =W10/W11-1 -> 0.017414459 | Y11: =Y10+W11 -> 5.6617312 | Z11: =(1-W11)/(0.5*Y11) -> 0.034202115
A12: 8 | B12: =IF(Inputs!C35="","",Inputs!C35) -> 30 | C12: =IF(B12<>"",A12,C11) -> 8 | D12: =IF(B12<>"",A12,D13) -> 8 | E12: =IF(B12<>"",B12,IF(AND(C12>0,D12>0),INDEX($B$5:$B$34,C12)+(INDEX($B$5:$B$34,D12)-INDEX($B$5:$B$34,C12))*(A12-C12)/(D12-C12),IF(C12>0,INDEX($B$5:$B$34,C12),IF(D12>0,INDEX($B$5:$B$34,D12),NA())))) -> 30 | F12: =IF(B12<>"","quoted",IF(AND(C12>0,D12>0),"interpolated","flat extrapolation")) -> quoted | G12: =IF(Inputs!D35="","",Inputs!D35) -> 0.03804 | H12: =IF(G12<>"",A12,H11) -> 8 | I12: =IF(G12<>"",A12,I13) -> 8 | J12: =IF(G12<>"",G12,IF(AND(H12>0,I12>0),INDEX($G$5:$G$34,H12)+(INDEX($G$5:$G$34,I12)-INDEX($G$5:$G$34,H12))*(A12-H12)/(I12-H12),IF(H12>0,INDEX($G$5:$G$34,H12),IF(I12>0,INDEX($G$5:$G$34,I12),NA())))) -> 0.03804 | K12: =2*((1+J12/Inputs!$C$18)^(Inputs!$C$18/2)-1) -> 0.037684961 | L12: =IF(G12<>"","quoted",IF(AND(H12>0,I12>0),"interpolated","flat extrapolation")) -> quoted | M12: =IF(Inputs!E35="","",Inputs!E35) -> 0.0345 | N12: =IF(M12<>"",A12,N11) -> 8 | O12: =IF(M12<>"",A12,O13) -> 8 | P12: =IF(M12<>"",M12,IF(AND(N12>0,O12>0),INDEX($M$5:$M$34,N12)+(INDEX($M$5:$M$34,O12)-INDEX($M$5:$M$34,N12))*(A12-N12)/(O12-N12),IF(N12>0,INDEX($M$5:$M$34,N12),IF(O12>0,INDEX($M$5:$M$34,O12),NA())))) -> 0.0345 | Q12: =(1-P12*Inputs!$C$16*R11)/(1+P12*Inputs!$C$16) -> 0.76223075 | R12: =R11+Q12 -> 6.8918624 | S12: =IF(M12<>"","quoted",IF(AND(N12>0,O12>0),"interpolated","flat extrapolation")) -> quoted | U12: 7 | V12: =U12/2 -> 3.5 | W12: =SQRT(INDEX($Q$5:$Q$34,3)*INDEX($Q$5:$Q$34,4)) -> 0.88817134 | X12: =W11/W12-1 -> 0.016896594 | Y12: =Y11+W12 -> 6.5499025 | Z12: =(1-W12)/(0.5*Y12) -> 0.034146664
A13: 9 | B13: =IF(Inputs!C36="","",Inputs!C36) -> 37 | C13: =IF(B13<>"",A13,C12) -> 9 | D13: =IF(B13<>"",A13,D14) -> 9 | E13: =IF(B13<>"",B13,IF(AND(C13>0,D13>0),INDEX($B$5:$B$34,C13)+(INDEX($B$5:$B$34,D13)-INDEX($B$5:$B$34,C13))*(A13-C13)/(D13-C13),IF(C13>0,INDEX($B$5:$B$34,C13),IF(D13>0,INDEX($B$5:$B$34,D13),NA())))) -> 37 | F13: =IF(B13<>"","quoted",IF(AND(C13>0,D13>0),"interpolated","flat extrapolation")) -> quoted | G13: =IF(Inputs!D36="","",Inputs!D36) -> 0.03888 | H13: =IF(G13<>"",A13,H12) -> 9 | I13: =IF(G13<>"",A13,I14) -> 9 | J13: =IF(G13<>"",G13,IF(AND(H13>0,I13>0),INDEX($G$5:$G$34,H13)+(INDEX($G$5:$G$34,I13)-INDEX($G$5:$G$34,H13))*(A13-H13)/(I13-H13),IF(H13>0,INDEX($G$5:$G$34,H13),IF(I13>0,INDEX($G$5:$G$34,I13),NA())))) -> 0.03888 | K13: =2*((1+J13/Inputs!$C$18)^(Inputs!$C$18/2)-1) -> 0.038509259 | L13: =IF(G13<>"","quoted",IF(AND(H13>0,I13>0),"interpolated","flat extrapolation")) -> quoted | M13: =IF(Inputs!E36="","",Inputs!E36) | N13: =IF(M13<>"",A13,N12) -> 8 | O13: =IF(M13<>"",A13,O14) -> 10 | P13: =IF(M13<>"",M13,IF(AND(N13>0,O13>0),INDEX($M$5:$M$34,N13)+(INDEX($M$5:$M$34,O13)-INDEX($M$5:$M$34,N13))*(A13-N13)/(O13-N13),IF(N13>0,INDEX($M$5:$M$34,N13),IF(O13>0,INDEX($M$5:$M$34,O13),NA())))) -> 0.0346 | Q13: =(1-P13*Inputs!$C$16*R12)/(1+P13*Inputs!$C$16) -> 0.73607342 | R13: =R12+Q13 -> 7.6279358 | S13: =IF(M13<>"","quoted",IF(AND(N13>0,O13>0),"interpolated","flat extrapolation")) -> interpolated | U13: 8 | V13: =U13/2 -> 4 | W13: =INDEX($Q$5:$Q$34,4) -> 0.87341362 | X13: =W12/W13-1 -> 0.016896594 | Y13: =Y12+W13 -> 7.4233161 | Z13: =(1-W13)/(0.5*Y13) -> 0.034105075
A14: 10 | B14: =IF(Inputs!C37="","",Inputs!C37) -> 42 | C14: =IF(B14<>"",A14,C13) -> 10 | D14: =IF(B14<>"",A14,D15) -> 10 | E14: =IF(B14<>"",B14,IF(AND(C14>0,D14>0),INDEX($B$5:$B$34,C14)+(INDEX($B$5:$B$34,D14)-INDEX($B$5:$B$34,C14))*(A14-C14)/(D14-C14),IF(C14>0,INDEX($B$5:$B$34,C14),IF(D14>0,INDEX($B$5:$B$34,D14),NA())))) -> 42 | F14: =IF(B14<>"","quoted",IF(AND(C14>0,D14>0),"interpolated","flat extrapolation")) -> quoted | G14: =IF(Inputs!D37="","",Inputs!D37) -> 0.03942 | H14: =IF(G14<>"",A14,H13) -> 10 | I14: =IF(G14<>"",A14,I15) -> 10 | J14: =IF(G14<>"",G14,IF(AND(H14>0,I14>0),INDEX($G$5:$G$34,H14)+(INDEX($G$5:$G$34,I14)-INDEX($G$5:$G$34,H14))*(A14-H14)/(I14-H14),IF(H14>0,INDEX($G$5:$G$34,H14),IF(I14>0,INDEX($G$5:$G$34,I14),NA())))) -> 0.03942 | K14: =2*((1+J14/Inputs!$C$18)^(Inputs!$C$18/2)-1) -> 0.039038989 | L14: =IF(G14<>"","quoted",IF(AND(H14>0,I14>0),"interpolated","flat extrapolation")) -> quoted | M14: =IF(Inputs!E37="","",Inputs!E37) -> 0.0347 | N14: =IF(M14<>"",A14,N13) -> 10 | O14: =IF(M14<>"",A14,O15) -> 10 | P14: =IF(M14<>"",M14,IF(AND(N14>0,O14>0),INDEX($M$5:$M$34,N14)+(INDEX($M$5:$M$34,O14)-INDEX($M$5:$M$34,N14))*(A14-N14)/(O14-N14),IF(N14>0,INDEX($M$5:$M$34,N14),IF(O14>0,INDEX($M$5:$M$34,O14),NA())))) -> 0.0347 | Q14: =(1-P14*Inputs!$C$16*R13)/(1+P14*Inputs!$C$16) -> 0.71065104 | R14: =R13+Q14 -> 8.3385869 | S14: =IF(M14<>"","quoted",IF(AND(N14>0,O14>0),"interpolated","flat extrapolation")) -> quoted | U14: 9 | V14: =U14/2 -> 4.5 | W14: =SQRT(INDEX($Q$5:$Q$34,4)*INDEX($Q$5:$Q$34,5)) -> 0.85876771 | X14: =W13/W14-1 -> 0.017054571 | Y14: =Y13+W14 -> 8.2820838 | Z14: =(1-W14)/(0.5*Y14) -> 0.034105496
A15: 11 | B15: =IF(Inputs!C38="","",Inputs!C38) -> 46 | C15: =IF(B15<>"",A15,C14) -> 11 | D15: =IF(B15<>"",A15,D16) -> 11 | E15: =IF(B15<>"",B15,IF(AND(C15>0,D15>0),INDEX($B$5:$B$34,C15)+(INDEX($B$5:$B$34,D15)-INDEX($B$5:$B$34,C15))*(A15-C15)/(D15-C15),IF(C15>0,INDEX($B$5:$B$34,C15),IF(D15>0,INDEX($B$5:$B$34,D15),NA())))) -> 46 | F15: =IF(B15<>"","quoted",IF(AND(C15>0,D15>0),"interpolated","flat extrapolation")) -> quoted | G15: =IF(Inputs!D38="","",Inputs!D38) -> 0.03995 | H15: =IF(G15<>"",A15,H14) -> 11 | I15: =IF(G15<>"",A15,I16) -> 11 | J15: =IF(G15<>"",G15,IF(AND(H15>0,I15>0),INDEX($G$5:$G$34,H15)+(INDEX($G$5:$G$34,I15)-INDEX($G$5:$G$34,H15))*(A15-H15)/(I15-H15),IF(H15>0,INDEX($G$5:$G$34,H15),IF(I15>0,INDEX($G$5:$G$34,I15),NA())))) -> 0.03995 | K15: =2*((1+J15/Inputs!$C$18)^(Inputs!$C$18/2)-1) -> 0.039558776 | L15: =IF(G15<>"","quoted",IF(AND(H15>0,I15>0),"interpolated","flat extrapolation")) -> quoted | M15: =IF(Inputs!E38="","",Inputs!E38) | N15: =IF(M15<>"",A15,N14) -> 10 | O15: =IF(M15<>"",A15,O16) -> 15 | P15: =IF(M15<>"",M15,IF(AND(N15>0,O15>0),INDEX($M$5:$M$34,N15)+(INDEX($M$5:$M$34,O15)-INDEX($M$5:$M$34,N15))*(A15-N15)/(O15-N15),IF(N15>0,INDEX($M$5:$M$34,N15),IF(O15>0,INDEX($M$5:$M$34,O15),NA())))) -> 0.03478 | Q15: =(1-P15*Inputs!$C$16*R14)/(1+P15*Inputs!$C$16) -> 0.68612067 | R15: =R14+Q15 -> 9.0247075 | S15: =IF(M15<>"","quoted",IF(AND(N15>0,O15>0),"interpolated","flat extrapolation")) -> interpolated | U15: 10 | V15: =U15/2 -> 5 | W15: =INDEX($Q$5:$Q$34,5) -> 0.84436739 | X15: =W14/W15-1 -> 0.017054571 | Y15: =Y14+W15 -> 9.1264512 | Z15: =(1-W15)/(0.5*Y15) -> 0.034105834
A16: 12 | B16: =IF(Inputs!C39="","",Inputs!C39) | C16: =IF(B16<>"",A16,C15) -> 11 | D16: =IF(B16<>"",A16,D17) -> 14 | E16: =IF(B16<>"",B16,IF(AND(C16>0,D16>0),INDEX($B$5:$B$34,C16)+(INDEX($B$5:$B$34,D16)-INDEX($B$5:$B$34,C16))*(A16-C16)/(D16-C16),IF(C16>0,INDEX($B$5:$B$34,C16),IF(D16>0,INDEX($B$5:$B$34,D16),NA())))) -> 51 | F16: =IF(B16<>"","quoted",IF(AND(C16>0,D16>0),"interpolated","flat extrapolation")) -> interpolated | G16: =IF(Inputs!D39="","",Inputs!D39) | H16: =IF(G16<>"",A16,H15) -> 11 | I16: =IF(G16<>"",A16,I17) -> 14 | J16: =IF(G16<>"",G16,IF(AND(H16>0,I16>0),INDEX($G$5:$G$34,H16)+(INDEX($G$5:$G$34,I16)-INDEX($G$5:$G$34,H16))*(A16-H16)/(I16-H16),IF(H16>0,INDEX($G$5:$G$34,H16),IF(I16>0,INDEX($G$5:$G$34,I16),NA())))) -> 0.040626667 | K16: =2*((1+J16/Inputs!$C$18)^(Inputs!$C$18/2)-1) -> 0.04022221 | L16: =IF(G16<>"","quoted",IF(AND(H16>0,I16>0),"interpolated","flat extrapolation")) -> interpolated | M16: =IF(Inputs!E39="","",Inputs!E39) | N16: =IF(M16<>"",A16,N15) -> 10 | O16: =IF(M16<>"",A16,O17) -> 15 | P16: =IF(M16<>"",M16,IF(AND(N16>0,O16>0),INDEX($M$5:$M$34,N16)+(INDEX($M$5:$M$34,O16)-INDEX($M$5:$M$34,N16))*(A16-N16)/(O16-N16),IF(N16>0,INDEX($M$5:$M$34,N16),IF(O16>0,INDEX($M$5:$M$34,O16),NA())))) -> 0.03486 | Q16: =(1-P16*Inputs!$C$16*R15)/(1+P16*Inputs!$C$16) -> 0.66231055 | R16: =R15+Q16 -> 9.6870181 | S16: =IF(M16<>"","quoted",IF(AND(N16>0,O16>0),"interpolated","flat extrapolation")) -> interpolated | U16: 11 | V16: =U16/2 -> 5.5 | W16: =SQRT(INDEX($Q$5:$Q$34,5)*INDEX($Q$5:$Q$34,6)) -> 0.83020854 | X16: =W15/W16-1 -> 0.017054571 | Y16: =Y15+W16 -> 9.9566598 | Z16: =(1-W16)/(0.5*Y16) -> 0.03410611
A17: 13 | B17: =IF(Inputs!C40="","",Inputs!C40) | C17: =IF(B17<>"",A17,C16) -> 11 | D17: =IF(B17<>"",A17,D18) -> 14 | E17: =IF(B17<>"",B17,IF(AND(C17>0,D17>0),INDEX($B$5:$B$34,C17)+(INDEX($B$5:$B$34,D17)-INDEX($B$5:$B$34,C17))*(A17-C17)/(D17-C17),IF(C17>0,INDEX($B$5:$B$34,C17),IF(D17>0,INDEX($B$5:$B$34,D17),NA())))) -> 56 | F17: =IF(B17<>"","quoted",IF(AND(C17>0,D17>0),"interpolated","flat extrapolation")) -> interpolated | G17: =IF(Inputs!D40="","",Inputs!D40) | H17: =IF(G17<>"",A17,H16) -> 11 | I17: =IF(G17<>"",A17,I18) -> 14 | J17: =IF(G17<>"",G17,IF(AND(H17>0,I17>0),INDEX($G$5:$G$34,H17)+(INDEX($G$5:$G$34,I17)-INDEX($G$5:$G$34,H17))*(A17-H17)/(I17-H17),IF(H17>0,INDEX($G$5:$G$34,H17),IF(I17>0,INDEX($G$5:$G$34,I17),NA())))) -> 0.041303333 | K17: =2*((1+J17/Inputs!$C$18)^(Inputs!$C$18/2)-1) -> 0.040885429 | L17: =IF(G17<>"","quoted",IF(AND(H17>0,I17>0),"interpolated","flat extrapolation")) -> interpolated | M17: =IF(Inputs!E40="","",Inputs!E40) | N17: =IF(M17<>"",A17,N16) -> 10 | O17: =IF(M17<>"",A17,O18) -> 15 | P17: =IF(M17<>"",M17,IF(AND(N17>0,O17>0),INDEX($M$5:$M$34,N17)+(INDEX($M$5:$M$34,O17)-INDEX($M$5:$M$34,N17))*(A17-N17)/(O17-N17),IF(N17>0,INDEX($M$5:$M$34,N17),IF(O17>0,INDEX($M$5:$M$34,O17),NA())))) -> 0.03494 | Q17: =(1-P17*Inputs!$C$16*R16)/(1+P17*Inputs!$C$16) -> 0.63920187 | R17: =R16+Q17 -> 10.32622 | S17: =IF(M17<>"","quoted",IF(AND(N17>0,O17>0),"interpolated","flat extrapolation")) -> interpolated | U17: 12 | V17: =U17/2 -> 6 | W17: =INDEX($Q$5:$Q$34,6) -> 0.81628711 | X17: =W16/W17-1 -> 0.017054571 | Y17: =Y16+W17 -> 10.772947 | Z17: =(1-W17)/(0.5*Y17) -> 0.034106339
A18: 14 | B18: =IF(Inputs!C41="","",Inputs!C41) -> 61 | C18: =IF(B18<>"",A18,C17) -> 14 | D18: =IF(B18<>"",A18,D19) -> 14 | E18: =IF(B18<>"",B18,IF(AND(C18>0,D18>0),INDEX($B$5:$B$34,C18)+(INDEX($B$5:$B$34,D18)-INDEX($B$5:$B$34,C18))*(A18-C18)/(D18-C18),IF(C18>0,INDEX($B$5:$B$34,C18),IF(D18>0,INDEX($B$5:$B$34,D18),NA())))) -> 61 | F18: =IF(B18<>"","quoted",IF(AND(C18>0,D18>0),"interpolated","flat extrapolation")) -> quoted | G18: =IF(Inputs!D41="","",Inputs!D41) -> 0.04198 | H18: =IF(G18<>"",A18,H17) -> 14 | I18: =IF(G18<>"",A18,I19) -> 14 | J18: =IF(G18<>"",G18,IF(AND(H18>0,I18>0),INDEX($G$5:$G$34,H18)+(INDEX($G$5:$G$34,I18)-INDEX($G$5:$G$34,H18))*(A18-H18)/(I18-H18),IF(H18>0,INDEX($G$5:$G$34,H18),IF(I18>0,INDEX($G$5:$G$34,I18),NA())))) -> 0.04198 | K18: =2*((1+J18/Inputs!$C$18)^(Inputs!$C$18/2)-1) -> 0.041548432 | L18: =IF(G18<>"","quoted",IF(AND(H18>0,I18>0),"interpolated","flat extrapolation")) -> quoted | M18: =IF(Inputs!E41="","",Inputs!E41) | N18: =IF(M18<>"",A18,N17) -> 10 | O18: =IF(M18<>"",A18,O19) -> 15 | P18: =IF(M18<>"",M18,IF(AND(N18>0,O18>0),INDEX($M$5:$M$34,N18)+(INDEX($M$5:$M$34,O18)-INDEX($M$5:$M$34,N18))*(A18-N18)/(O18-N18),IF(N18>0,INDEX($M$5:$M$34,N18),IF(O18>0,INDEX($M$5:$M$34,O18),NA())))) -> 0.03502 | Q18: =(1-P18*Inputs!$C$16*R17)/(1+P18*Inputs!$C$16) -> 0.61677627 | R18: =R17+Q18 -> 10.942996 | S18: =IF(M18<>"","quoted",IF(AND(N18>0,O18>0),"interpolated","flat extrapolation")) -> interpolated | U18: 13 | V18: =U18/2 -> 6.5 | W18: =SQRT(INDEX($Q$5:$Q$34,6)*INDEX($Q$5:$Q$34,7)) -> 0.80259913 | X18: =W17/W18-1 -> 0.017054571 | Y18: =Y17+W18 -> 11.575546 | Z18: =(1-W18)/(0.5*Y18) -> 0.034106534
A19: 15 | B19: =IF(Inputs!C42="","",Inputs!C42) -> 65 | C19: =IF(B19<>"",A19,C18) -> 15 | D19: =IF(B19<>"",A19,D20) -> 15 | E19: =IF(B19<>"",B19,IF(AND(C19>0,D19>0),INDEX($B$5:$B$34,C19)+(INDEX($B$5:$B$34,D19)-INDEX($B$5:$B$34,C19))*(A19-C19)/(D19-C19),IF(C19>0,INDEX($B$5:$B$34,C19),IF(D19>0,INDEX($B$5:$B$34,D19),NA())))) -> 65 | F19: =IF(B19<>"","quoted",IF(AND(C19>0,D19>0),"interpolated","flat extrapolation")) -> quoted | G19: =IF(Inputs!D42="","",Inputs!D42) -> 0.04256 | H19: =IF(G19<>"",A19,H18) -> 15 | I19: =IF(G19<>"",A19,I20) -> 15 | J19: =IF(G19<>"",G19,IF(AND(H19>0,I19>0),INDEX($G$5:$G$34,H19)+(INDEX($G$5:$G$34,I19)-INDEX($G$5:$G$34,H19))*(A19-H19)/(I19-H19),IF(H19>0,INDEX($G$5:$G$34,H19),IF(I19>0,INDEX($G$5:$G$34,I19),NA())))) -> 0.04256 | K19: =2*((1+J19/Inputs!$C$18)^(Inputs!$C$18/2)-1) -> 0.042116549 | L19: =IF(G19<>"","quoted",IF(AND(H19>0,I19>0),"interpolated","flat extrapolation")) -> quoted | M19: =IF(Inputs!E42="","",Inputs!E42) -> 0.0351 | N19: =IF(M19<>"",A19,N18) -> 15 | O19: =IF(M19<>"",A19,O20) -> 15 | P19: =IF(M19<>"",M19,IF(AND(N19>0,O19>0),INDEX($M$5:$M$34,N19)+(INDEX($M$5:$M$34,O19)-INDEX($M$5:$M$34,N19))*(A19-N19)/(O19-N19),IF(N19>0,INDEX($M$5:$M$34,N19),IF(O19>0,INDEX($M$5:$M$34,O19),NA())))) -> 0.0351 | Q19: =(1-P19*Inputs!$C$16*R18)/(1+P19*Inputs!$C$16) -> 0.59501578 | R19: =R18+Q19 -> 11.538012 | S19: =IF(M19<>"","quoted",IF(AND(N19>0,O19>0),"interpolated","flat extrapolation")) -> quoted | U19: 14 | V19: =U19/2 -> 7 | W19: =INDEX($Q$5:$Q$34,7) -> 0.78914067 | X19: =W18/W19-1 -> 0.017054571 | Y19: =Y18+W19 -> 12.364687 | Z19: =(1-W19)/(0.5*Y19) -> 0.0341067
A20: 16 | B20: =IF(Inputs!C43="","",Inputs!C43) | C20: =IF(B20<>"",A20,C19) -> 15 | D20: =IF(B20<>"",A20,D21) -> 18 | E20: =IF(B20<>"",B20,IF(AND(C20>0,D20>0),INDEX($B$5:$B$34,C20)+(INDEX($B$5:$B$34,D20)-INDEX($B$5:$B$34,C20))*(A20-C20)/(D20-C20),IF(C20>0,INDEX($B$5:$B$34,C20),IF(D20>0,INDEX($B$5:$B$34,D20),NA())))) -> 68 | F20: =IF(B20<>"","quoted",IF(AND(C20>0,D20>0),"interpolated","flat extrapolation")) -> interpolated | G20: =IF(Inputs!D43="","",Inputs!D43) | H20: =IF(G20<>"",A20,H19) -> 15 | I20: =IF(G20<>"",A20,I21) -> 18 | J20: =IF(G20<>"",G20,IF(AND(H20>0,I20>0),INDEX($G$5:$G$34,H20)+(INDEX($G$5:$G$34,I20)-INDEX($G$5:$G$34,H20))*(A20-H20)/(I20-H20),IF(H20>0,INDEX($G$5:$G$34,H20),IF(I20>0,INDEX($G$5:$G$34,I20),NA())))) -> 0.042773333 | K20: =2*((1+J20/Inputs!$C$18)^(Inputs!$C$18/2)-1) -> 0.042325472 | L20: =IF(G20<>"","quoted",IF(AND(H20>0,I20>0),"interpolated","flat extrapolation")) -> interpolated | M20: =IF(Inputs!E43="","",Inputs!E43) | N20: =IF(M20<>"",A20,N19) -> 15 | O20: =IF(M20<>"",A20,O21) -> 20 | P20: =IF(M20<>"",M20,IF(AND(N20>0,O20>0),INDEX($M$5:$M$34,N20)+(INDEX($M$5:$M$34,O20)-INDEX($M$5:$M$34,N20))*(A20-N20)/(O20-N20),IF(N20>0,INDEX($M$5:$M$34,N20),IF(O20>0,INDEX($M$5:$M$34,O20),NA())))) -> 0.03502 | Q20: =(1-P20*Inputs!$C$16*R19)/(1+P20*Inputs!$C$16) -> 0.57577517 | R20: =R19+Q20 -> 12.113787 | S20: =IF(M20<>"","quoted",IF(AND(N20>0,O20>0),"interpolated","flat extrapolation")) -> interpolated | U20: 15 | V20: =U20/2 -> 7.5 | W20: =SQRT(INDEX($Q$5:$Q$34,7)*INDEX($Q$5:$Q$34,8)) -> 0.77556901 | X20: =W19/W20-1 -> 0.017498978 | Y20: =Y19+W20 -> 13.140256 | Z20: =(1-W20)/(0.5*Y20) -> 0.034159304
A21: 17 | B21: =IF(Inputs!C44="","",Inputs!C44) | C21: =IF(B21<>"",A21,C20) -> 15 | D21: =IF(B21<>"",A21,D22) -> 18 | E21: =IF(B21<>"",B21,IF(AND(C21>0,D21>0),INDEX($B$5:$B$34,C21)+(INDEX($B$5:$B$34,D21)-INDEX($B$5:$B$34,C21))*(A21-C21)/(D21-C21),IF(C21>0,INDEX($B$5:$B$34,C21),IF(D21>0,INDEX($B$5:$B$34,D21),NA())))) -> 71 | F21: =IF(B21<>"","quoted",IF(AND(C21>0,D21>0),"interpolated","flat extrapolation")) -> interpolated | G21: =IF(Inputs!D44="","",Inputs!D44) | H21: =IF(G21<>"",A21,H20) -> 15 | I21: =IF(G21<>"",A21,I22) -> 18 | J21: =IF(G21<>"",G21,IF(AND(H21>0,I21>0),INDEX($G$5:$G$34,H21)+(INDEX($G$5:$G$34,I21)-INDEX($G$5:$G$34,H21))*(A21-H21)/(I21-H21),IF(H21>0,INDEX($G$5:$G$34,H21),IF(I21>0,INDEX($G$5:$G$34,I21),NA())))) -> 0.042986667 | K21: =2*((1+J21/Inputs!$C$18)^(Inputs!$C$18/2)-1) -> 0.042534373 | L21: =IF(G21<>"","quoted",IF(AND(H21>0,I21>0),"interpolated","flat extrapolation")) -> interpolated | M21: =IF(Inputs!E44="","",Inputs!E44) | N21: =IF(M21<>"",A21,N20) -> 15 | O21: =IF(M21<>"",A21,O22) -> 20 | P21: =IF(M21<>"",M21,IF(AND(N21>0,O21>0),INDEX($M$5:$M$34,N21)+(INDEX($M$5:$M$34,O21)-INDEX($M$5:$M$34,N21))*(A21-N21)/(O21-N21),IF(N21>0,INDEX($M$5:$M$34,N21),IF(O21>0,INDEX($M$5:$M$34,O21),NA())))) -> 0.03494 | Q21: =(1-P21*Inputs!$C$16*R20)/(1+P21*Inputs!$C$16) -> 0.55727315 | R21: =R20+Q21 -> 12.67106 | S21: =IF(M21<>"","quoted",IF(AND(N21>0,O21>0),"interpolated","flat extrapolation")) -> interpolated | U21: 16 | V21: =U21/2 -> 8 | W21: =INDEX($Q$5:$Q$34,8) -> 0.76223075 | X21: =W20/W21-1 -> 0.017498978 | Y21: =Y20+W21 -> 13.902486 | Z21: =(1-W21)/(0.5*Y21) -> 0.034205285
A22: 18 | B22: =IF(Inputs!C45="","",Inputs!C45) -> 74 | C22: =IF(B22<>"",A22,C21) -> 18 | D22: =IF(B22<>"",A22,D23) -> 18 | E22: =IF(B22<>"",B22,IF(AND(C22>0,D22>0),INDEX($B$5:$B$34,C22)+(INDEX($B$5:$B$34,D22)-INDEX($B$5:$B$34,C22))*(A22-C22)/(D22-C22),IF(C22>0,INDEX($B$5:$B$34,C22),IF(D22>0,INDEX($B$5:$B$34,D22),NA())))) -> 74 | F22: =IF(B22<>"","quoted",IF(AND(C22>0,D22>0),"interpolated","flat extrapolation")) -> quoted | G22: =IF(Inputs!D45="","",Inputs!D45) -> 0.0432 | H22: =IF(G22<>"",A22,H21) -> 18 | I22: =IF(G22<>"",A22,I23) -> 18 | J22: =IF(G22<>"",G22,IF(AND(H22>0,I22>0),INDEX($G$5:$G$34,H22)+(INDEX($G$5:$G$34,I22)-INDEX($G$5:$G$34,H22))*(A22-H22)/(I22-H22),IF(H22>0,INDEX($G$5:$G$34,H22),IF(I22>0,INDEX($G$5:$G$34,I22),NA())))) -> 0.0432 | K22: =2*((1+J22/Inputs!$C$18)^(Inputs!$C$18/2)-1) -> 0.042743254 | L22: =IF(G22<>"","quoted",IF(AND(H22>0,I22>0),"interpolated","flat extrapolation")) -> quoted | M22: =IF(Inputs!E45="","",Inputs!E45) | N22: =IF(M22<>"",A22,N21) -> 15 | O22: =IF(M22<>"",A22,O23) -> 20 | P22: =IF(M22<>"",M22,IF(AND(N22>0,O22>0),INDEX($M$5:$M$34,N22)+(INDEX($M$5:$M$34,O22)-INDEX($M$5:$M$34,N22))*(A22-N22)/(O22-N22),IF(N22>0,INDEX($M$5:$M$34,N22),IF(O22>0,INDEX($M$5:$M$34,O22),NA())))) -> 0.03486 | Q22: =(1-P22*Inputs!$C$16*R21)/(1+P22*Inputs!$C$16) -> 0.53948054 | R22: =R21+Q22 -> 13.210541 | S22: =IF(M22<>"","quoted",IF(AND(N22>0,O22>0),"interpolated","flat extrapolation")) -> interpolated | U22: 17 | V22: =U22/2 -> 8.5 | W22: =SQRT(INDEX($Q$5:$Q$34,8)*INDEX($Q$5:$Q$34,9)) -> 0.74903791 | X22: =W21/W22-1 -> 0.017613041 | Y22: =Y21+W22 -> 14.651524 | Z22: =(1-W22)/(0.5*Y22) -> 0.034257472
A23: 19 | B23: =IF(Inputs!C46="","",Inputs!C46) | C23: =IF(B23<>"",A23,C22) -> 18 | D23: =IF(B23<>"",A23,D24) -> 20 | E23: =IF(B23<>"",B23,IF(AND(C23>0,D23>0),INDEX($B$5:$B$34,C23)+(INDEX($B$5:$B$34,D23)-INDEX($B$5:$B$34,C23))*(A23-C23)/(D23-C23),IF(C23>0,INDEX($B$5:$B$34,C23),IF(D23>0,INDEX($B$5:$B$34,D23),NA())))) -> 76 | F23: =IF(B23<>"","quoted",IF(AND(C23>0,D23>0),"interpolated","flat extrapolation")) -> interpolated | G23: =IF(Inputs!D46="","",Inputs!D46) | H23: =IF(G23<>"",A23,H22) -> 18 | I23: =IF(G23<>"",A23,I24) -> 20 | J23: =IF(G23<>"",G23,IF(AND(H23>0,I23>0),INDEX($G$5:$G$34,H23)+(INDEX($G$5:$G$34,I23)-INDEX($G$5:$G$34,H23))*(A23-H23)/(I23-H23),IF(H23>0,INDEX($G$5:$G$34,H23),IF(I23>0,INDEX($G$5:$G$34,I23),NA())))) -> 0.043345 | K23: =2*((1+J23/Inputs!$C$18)^(Inputs!$C$18/2)-1) -> 0.042885215 | L23: =IF(G23<>"","quoted",IF(AND(H23>0,I23>0),"interpolated","flat extrapolation")) -> interpolated | M23: =IF(Inputs!E46="","",Inputs!E46) | N23: =IF(M23<>"",A23,N22) -> 15 | O23: =IF(M23<>"",A23,O24) -> 20 | P23: =IF(M23<>"",M23,IF(AND(N23>0,O23>0),INDEX($M$5:$M$34,N23)+(INDEX($M$5:$M$34,O23)-INDEX($M$5:$M$34,N23))*(A23-N23)/(O23-N23),IF(N23>0,INDEX($M$5:$M$34,N23),IF(O23>0,INDEX($M$5:$M$34,O23),NA())))) -> 0.03478 | Q23: =(1-P23*Inputs!$C$16*R22)/(1+P23*Inputs!$C$16) -> 0.52236938 | R23: =R22+Q23 -> 13.73291 | S23: =IF(M23<>"","quoted",IF(AND(N23>0,O23>0),"interpolated","flat extrapolation")) -> interpolated | U23: 18 | V23: =U23/2 -> 9 | W23: =INDEX($Q$5:$Q$34,9) -> 0.73607342 | X23: =W22/W23-1 -> 0.017613041 | Y23: =Y22+W23 -> 15.387598 | Z23: =(1-W23)/(0.5*Y23) -> 0.034303805
A24: 20 | B24: =IF(Inputs!C47="","",Inputs!C47) -> 78 | C24: =IF(B24<>"",A24,C23) -> 20 | D24: =IF(B24<>"",A24,D25) -> 20 | E24: =IF(B24<>"",B24,IF(AND(C24>0,D24>0),INDEX($B$5:$B$34,C24)+(INDEX($B$5:$B$34,D24)-INDEX($B$5:$B$34,C24))*(A24-C24)/(D24-C24),IF(C24>0,INDEX($B$5:$B$34,C24),IF(D24>0,INDEX($B$5:$B$34,D24),NA())))) -> 78 | F24: =IF(B24<>"","quoted",IF(AND(C24>0,D24>0),"interpolated","flat extrapolation")) -> quoted | G24: =IF(Inputs!D47="","",Inputs!D47) -> 0.04349 | H24: =IF(G24<>"",A24,H23) -> 20 | I24: =IF(G24<>"",A24,I25) -> 20 | J24: =IF(G24<>"",G24,IF(AND(H24>0,I24>0),INDEX($G$5:$G$34,H24)+(INDEX($G$5:$G$34,I24)-INDEX($G$5:$G$34,H24))*(A24-H24)/(I24-H24),IF(H24>0,INDEX($G$5:$G$34,H24),IF(I24>0,INDEX($G$5:$G$34,I24),NA())))) -> 0.04349 | K24: =2*((1+J24/Inputs!$C$18)^(Inputs!$C$18/2)-1) -> 0.043027166 | L24: =IF(G24<>"","quoted",IF(AND(H24>0,I24>0),"interpolated","flat extrapolation")) -> quoted | M24: =IF(Inputs!E47="","",Inputs!E47) -> 0.0347 | N24: =IF(M24<>"",A24,N23) -> 20 | O24: =IF(M24<>"",A24,O25) -> 20 | P24: =IF(M24<>"",M24,IF(AND(N24>0,O24>0),INDEX($M$5:$M$34,N24)+(INDEX($M$5:$M$34,O24)-INDEX($M$5:$M$34,N24))*(A24-N24)/(O24-N24),IF(N24>0,INDEX($M$5:$M$34,N24),IF(O24>0,INDEX($M$5:$M$34,O24),NA())))) -> 0.0347 | Q24: =(1-P24*Inputs!$C$16*R23)/(1+P24*Inputs!$C$16) -> 0.50591284 | R24: =R23+Q24 -> 14.238823 | S24: =IF(M24<>"","quoted",IF(AND(N24>0,O24>0),"interpolated","flat extrapolation")) -> quoted | U24: 19 | V24: =U24/2 -> 9.5 | W24: =SQRT(INDEX($Q$5:$Q$34,9)*INDEX($Q$5:$Q$34,10)) -> 0.72325054 | X24: =W23/W24-1 -> 0.017729519 | Y24: =Y23+W24 -> 16.110848 | Z24: =(1-W24)/(0.5*Y24) -> 0.034355666
A25: 21 | B25: =IF(Inputs!C48="","",Inputs!C48) | C25: =IF(B25<>"",A25,C24) -> 20 | D25: =IF(B25<>"",A25,D26) -> 25 | E25: =IF(B25<>"",B25,IF(AND(C25>0,D25>0),INDEX($B$5:$B$34,C25)+(INDEX($B$5:$B$34,D25)-INDEX($B$5:$B$34,C25))*(A25-C25)/(D25-C25),IF(C25>0,INDEX($B$5:$B$34,C25),IF(D25>0,INDEX($B$5:$B$34,D25),NA())))) -> 80.2 | F25: =IF(B25<>"","quoted",IF(AND(C25>0,D25>0),"interpolated","flat extrapolation")) -> interpolated | G25: =IF(Inputs!D48="","",Inputs!D48) | H25: =IF(G25<>"",A25,H24) -> 20 | I25: =IF(G25<>"",A25,I26) -> 25 | J25: =IF(G25<>"",G25,IF(AND(H25>0,I25>0),INDEX($G$5:$G$34,H25)+(INDEX($G$5:$G$34,I25)-INDEX($G$5:$G$34,H25))*(A25-H25)/(I25-H25),IF(H25>0,INDEX($G$5:$G$34,H25),IF(I25>0,INDEX($G$5:$G$34,I25),NA())))) -> 0.04349 | K25: =2*((1+J25/Inputs!$C$18)^(Inputs!$C$18/2)-1) -> 0.043027166 | L25: =IF(G25<>"","quoted",IF(AND(H25>0,I25>0),"interpolated","flat extrapolation")) -> interpolated | M25: =IF(Inputs!E48="","",Inputs!E48) | N25: =IF(M25<>"",A25,N24) -> 20 | O25: =IF(M25<>"",A25,O26) -> 30 | P25: =IF(M25<>"",M25,IF(AND(N25>0,O25>0),INDEX($M$5:$M$34,N25)+(INDEX($M$5:$M$34,O25)-INDEX($M$5:$M$34,N25))*(A25-N25)/(O25-N25),IF(N25>0,INDEX($M$5:$M$34,N25),IF(O25>0,INDEX($M$5:$M$34,O25),NA())))) -> 0.03452 | Q25: =(1-P25*Inputs!$C$16*R24)/(1+P25*Inputs!$C$16) -> 0.49150894 | R25: =R24+Q25 -> 14.730332 | S25: =IF(M25<>"","quoted",IF(AND(N25>0,O25>0),"interpolated","flat extrapolation")) -> interpolated | U25: 20 | V25: =U25/2 -> 10 | W25: =INDEX($Q$5:$Q$34,10) -> 0.71065104 | X25: =W24/W25-1 -> 0.017729519 | Y25: =Y24+W25 -> 16.821499 | Z25: =(1-W25)/(0.5*Y25) -> 0.03440228
A26: 22 | B26: =IF(Inputs!C49="","",Inputs!C49) | C26: =IF(B26<>"",A26,C25) -> 20 | D26: =IF(B26<>"",A26,D27) -> 25 | E26: =IF(B26<>"",B26,IF(AND(C26>0,D26>0),INDEX($B$5:$B$34,C26)+(INDEX($B$5:$B$34,D26)-INDEX($B$5:$B$34,C26))*(A26-C26)/(D26-C26),IF(C26>0,INDEX($B$5:$B$34,C26),IF(D26>0,INDEX($B$5:$B$34,D26),NA())))) -> 82.4 | F26: =IF(B26<>"","quoted",IF(AND(C26>0,D26>0),"interpolated","flat extrapolation")) -> interpolated | G26: =IF(Inputs!D49="","",Inputs!D49) | H26: =IF(G26<>"",A26,H25) -> 20 | I26: =IF(G26<>"",A26,I27) -> 25 | J26: =IF(G26<>"",G26,IF(AND(H26>0,I26>0),INDEX($G$5:$G$34,H26)+(INDEX($G$5:$G$34,I26)-INDEX($G$5:$G$34,H26))*(A26-H26)/(I26-H26),IF(H26>0,INDEX($G$5:$G$34,H26),IF(I26>0,INDEX($G$5:$G$34,I26),NA())))) -> 0.04349 | K26: =2*((1+J26/Inputs!$C$18)^(Inputs!$C$18/2)-1) -> 0.043027166 | L26: =IF(G26<>"","quoted",IF(AND(H26>0,I26>0),"interpolated","flat extrapolation")) -> interpolated | M26: =IF(Inputs!E49="","",Inputs!E49) | N26: =IF(M26<>"",A26,N25) -> 20 | O26: =IF(M26<>"",A26,O27) -> 30 | P26: =IF(M26<>"",M26,IF(AND(N26>0,O26>0),INDEX($M$5:$M$34,N26)+(INDEX($M$5:$M$34,O26)-INDEX($M$5:$M$34,N26))*(A26-N26)/(O26-N26),IF(N26>0,INDEX($M$5:$M$34,N26),IF(O26>0,INDEX($M$5:$M$34,O26),NA())))) -> 0.03434 | Q26: =(1-P26*Inputs!$C$16*R25)/(1+P26*Inputs!$C$16) -> 0.47775431 | R26: =R25+Q26 -> 15.208086 | S26: =IF(M26<>"","quoted",IF(AND(N26>0,O26>0),"interpolated","flat extrapolation")) -> interpolated | U26: 21 | V26: =U26/2 -> 10.5 | W26: =SQRT(INDEX($Q$5:$Q$34,10)*INDEX($Q$5:$Q$34,11)) -> 0.69827814 | X26: =W25/W26-1 -> 0.017719145 | Y26: =Y25+W26 -> 17.519777 | Z26: =(1-W26)/(0.5*Y26) -> 0.034443572
A27: 23 | B27: =IF(Inputs!C50="","",Inputs!C50) | C27: =IF(B27<>"",A27,C26) -> 20 | D27: =IF(B27<>"",A27,D28) -> 25 | E27: =IF(B27<>"",B27,IF(AND(C27>0,D27>0),INDEX($B$5:$B$34,C27)+(INDEX($B$5:$B$34,D27)-INDEX($B$5:$B$34,C27))*(A27-C27)/(D27-C27),IF(C27>0,INDEX($B$5:$B$34,C27),IF(D27>0,INDEX($B$5:$B$34,D27),NA())))) -> 84.6 | F27: =IF(B27<>"","quoted",IF(AND(C27>0,D27>0),"interpolated","flat extrapolation")) -> interpolated | G27: =IF(Inputs!D50="","",Inputs!D50) | H27: =IF(G27<>"",A27,H26) -> 20 | I27: =IF(G27<>"",A27,I28) -> 25 | J27: =IF(G27<>"",G27,IF(AND(H27>0,I27>0),INDEX($G$5:$G$34,H27)+(INDEX($G$5:$G$34,I27)-INDEX($G$5:$G$34,H27))*(A27-H27)/(I27-H27),IF(H27>0,INDEX($G$5:$G$34,H27),IF(I27>0,INDEX($G$5:$G$34,I27),NA())))) -> 0.04349 | K27: =2*((1+J27/Inputs!$C$18)^(Inputs!$C$18/2)-1) -> 0.043027166 | L27: =IF(G27<>"","quoted",IF(AND(H27>0,I27>0),"interpolated","flat extrapolation")) -> interpolated | M27: =IF(Inputs!E50="","",Inputs!E50) | N27: =IF(M27<>"",A27,N26) -> 20 | O27: =IF(M27<>"",A27,O28) -> 30 | P27: =IF(M27<>"",M27,IF(AND(N27>0,O27>0),INDEX($M$5:$M$34,N27)+(INDEX($M$5:$M$34,O27)-INDEX($M$5:$M$34,N27))*(A27-N27)/(O27-N27),IF(N27>0,INDEX($M$5:$M$34,N27),IF(O27>0,INDEX($M$5:$M$34,O27),NA())))) -> 0.03416 | Q27: =(1-P27*Inputs!$C$16*R26)/(1+P27*Inputs!$C$16) -> 0.46462034 | R27: =R26+Q27 -> 15.672707 | S27: =IF(M27<>"","quoted",IF(AND(N27>0,O27>0),"interpolated","flat extrapolation")) -> interpolated | U27: 22 | V27: =U27/2 -> 11 | W27: =INDEX($Q$5:$Q$34,11) -> 0.68612067 | X27: =W26/W27-1 -> 0.017719145 | Y27: =Y26+W27 -> 18.205898 | Z27: =(1-W27)/(0.5*Y27) -> 0.03448106
A28: 24 | B28: =IF(Inputs!C51="","",Inputs!C51) | C28: =IF(B28<>"",A28,C27) -> 20 | D28: =IF(B28<>"",A28,D29) -> 25 | E28: =IF(B28<>"",B28,IF(AND(C28>0,D28>0),INDEX($B$5:$B$34,C28)+(INDEX($B$5:$B$34,D28)-INDEX($B$5:$B$34,C28))*(A28-C28)/(D28-C28),IF(C28>0,INDEX($B$5:$B$34,C28),IF(D28>0,INDEX($B$5:$B$34,D28),NA())))) -> 86.8 | F28: =IF(B28<>"","quoted",IF(AND(C28>0,D28>0),"interpolated","flat extrapolation")) -> interpolated | G28: =IF(Inputs!D51="","",Inputs!D51) | H28: =IF(G28<>"",A28,H27) -> 20 | I28: =IF(G28<>"",A28,I29) -> 25 | J28: =IF(G28<>"",G28,IF(AND(H28>0,I28>0),INDEX($G$5:$G$34,H28)+(INDEX($G$5:$G$34,I28)-INDEX($G$5:$G$34,H28))*(A28-H28)/(I28-H28),IF(H28>0,INDEX($G$5:$G$34,H28),IF(I28>0,INDEX($G$5:$G$34,I28),NA())))) -> 0.04349 | K28: =2*((1+J28/Inputs!$C$18)^(Inputs!$C$18/2)-1) -> 0.043027166 | L28: =IF(G28<>"","quoted",IF(AND(H28>0,I28>0),"interpolated","flat extrapolation")) -> interpolated | M28: =IF(Inputs!E51="","",Inputs!E51) | N28: =IF(M28<>"",A28,N27) -> 20 | O28: =IF(M28<>"",A28,O29) -> 30 | P28: =IF(M28<>"",M28,IF(AND(N28>0,O28>0),INDEX($M$5:$M$34,N28)+(INDEX($M$5:$M$34,O28)-INDEX($M$5:$M$34,N28))*(A28-N28)/(O28-N28),IF(N28>0,INDEX($M$5:$M$34,N28),IF(O28>0,INDEX($M$5:$M$34,O28),NA())))) -> 0.03398 | Q28: =(1-P28*Inputs!$C$16*R27)/(1+P28*Inputs!$C$16) -> 0.45207976 | R28: =R27+Q28 -> 16.124786 | S28: =IF(M28<>"","quoted",IF(AND(N28>0,O28>0),"interpolated","flat extrapolation")) -> interpolated | U28: 23 | V28: =U28/2 -> 11.5 | W28: =SQRT(INDEX($Q$5:$Q$34,11)*INDEX($Q$5:$Q$34,12)) -> 0.67411049 | X28: =W27/W28-1 -> 0.017816333 | Y28: =Y27+W28 -> 18.880009 | Z28: =(1-W28)/(0.5*Y28) -> 0.034522178
A29: 25 | B29: =IF(Inputs!C52="","",Inputs!C52) -> 89 | C29: =IF(B29<>"",A29,C28) -> 25 | D29: =IF(B29<>"",A29,D30) -> 25 | E29: =IF(B29<>"",B29,IF(AND(C29>0,D29>0),INDEX($B$5:$B$34,C29)+(INDEX($B$5:$B$34,D29)-INDEX($B$5:$B$34,C29))*(A29-C29)/(D29-C29),IF(C29>0,INDEX($B$5:$B$34,C29),IF(D29>0,INDEX($B$5:$B$34,D29),NA())))) -> 89 | F29: =IF(B29<>"","quoted",IF(AND(C29>0,D29>0),"interpolated","flat extrapolation")) -> quoted | G29: =IF(Inputs!D52="","",Inputs!D52) -> 0.04349 | H29: =IF(G29<>"",A29,H28) -> 25 | I29: =IF(G29<>"",A29,I30) -> 25 | J29: =IF(G29<>"",G29,IF(AND(H29>0,I29>0),INDEX($G$5:$G$34,H29)+(INDEX($G$5:$G$34,I29)-INDEX($G$5:$G$34,H29))*(A29-H29)/(I29-H29),IF(H29>0,INDEX($G$5:$G$34,H29),IF(I29>0,INDEX($G$5:$G$34,I29),NA())))) -> 0.04349 | K29: =2*((1+J29/Inputs!$C$18)^(Inputs!$C$18/2)-1) -> 0.043027166 | L29: =IF(G29<>"","quoted",IF(AND(H29>0,I29>0),"interpolated","flat extrapolation")) -> quoted | M29: =IF(Inputs!E52="","",Inputs!E52) | N29: =IF(M29<>"",A29,N28) -> 20 | O29: =IF(M29<>"",A29,O30) -> 30 | P29: =IF(M29<>"",M29,IF(AND(N29>0,O29>0),INDEX($M$5:$M$34,N29)+(INDEX($M$5:$M$34,O29)-INDEX($M$5:$M$34,N29))*(A29-N29)/(O29-N29),IF(N29>0,INDEX($M$5:$M$34,N29),IF(O29>0,INDEX($M$5:$M$34,O29),NA())))) -> 0.0338 | Q29: =(1-P29*Inputs!$C$16*R28)/(1+P29*Inputs!$C$16) -> 0.44010661 | R29: =R28+Q29 -> 16.564893 | S29: =IF(M29<>"","quoted",IF(AND(N29>0,O29>0),"interpolated","flat extrapolation")) -> interpolated | U29: 24 | V29: =U29/2 -> 12 | W29: =INDEX($Q$5:$Q$34,12) -> 0.66231055 | X29: =W28/W29-1 -> 0.017816333 | Y29: =Y28+W29 -> 19.542319 | Z29: =(1-W29)/(0.5*Y29) -> 0.034559813
A30: 26 | B30: =IF(Inputs!C53="","",Inputs!C53) | C30: =IF(B30<>"",A30,C29) -> 25 | D30: =IF(B30<>"",A30,D31) -> 28 | E30: =IF(B30<>"",B30,IF(AND(C30>0,D30>0),INDEX($B$5:$B$34,C30)+(INDEX($B$5:$B$34,D30)-INDEX($B$5:$B$34,C30))*(A30-C30)/(D30-C30),IF(C30>0,INDEX($B$5:$B$34,C30),IF(D30>0,INDEX($B$5:$B$34,D30),NA())))) -> 90 | F30: =IF(B30<>"","quoted",IF(AND(C30>0,D30>0),"interpolated","flat extrapolation")) -> interpolated | G30: =IF(Inputs!D53="","",Inputs!D53) | H30: =IF(G30<>"",A30,H29) -> 25 | I30: =IF(G30<>"",A30,I31) -> 28 | J30: =IF(G30<>"",G30,IF(AND(H30>0,I30>0),INDEX($G$5:$G$34,H30)+(INDEX($G$5:$G$34,I30)-INDEX($G$5:$G$34,H30))*(A30-H30)/(I30-H30),IF(H30>0,INDEX($G$5:$G$34,H30),IF(I30>0,INDEX($G$5:$G$34,I30),NA())))) -> 0.04358 | K30: =2*((1+J30/Inputs!$C$18)^(Inputs!$C$18/2)-1) -> 0.043115268 | L30: =IF(G30<>"","quoted",IF(AND(H30>0,I30>0),"interpolated","flat extrapolation")) -> interpolated | M30: =IF(Inputs!E53="","",Inputs!E53) | N30: =IF(M30<>"",A30,N29) -> 20 | O30: =IF(M30<>"",A30,O31) -> 30 | P30: =IF(M30<>"",M30,IF(AND(N30>0,O30>0),INDEX($M$5:$M$34,N30)+(INDEX($M$5:$M$34,O30)-INDEX($M$5:$M$34,N30))*(A30-N30)/(O30-N30),IF(N30>0,INDEX($M$5:$M$34,N30),IF(O30>0,INDEX($M$5:$M$34,O30),NA())))) -> 0.03362 | Q30: =(1-P30*Inputs!$C$16*R29)/(1+P30*Inputs!$C$16) -> 0.4286762 | R30: =R29+Q30 -> 16.993569 | S30: =IF(M30<>"","quoted",IF(AND(N30>0,O30>0),"interpolated","flat extrapolation")) -> interpolated | U30: 25 | V30: =U30/2 -> 12.5 | W30: =SQRT(INDEX($Q$5:$Q$34,12)*INDEX($Q$5:$Q$34,13)) -> 0.65065363 | X30: =W29/W30-1 -> 0.017915708 | Y30: =Y29+W30 -> 20.192973 | Z30: =(1-W30)/(0.5*Y30) -> 0.034600787
